Workbook

Sheet Cover
G6: RHEINMETALL DCF Valuation
G7: Forecasts, CoC, Multiples, Valuation & Sensitivity analysis
G12: DCF Analysis
C20: ANTÓNIO MARIA
C21: DE BOURA LOBO CAMPINOS
A35: (model inspired by JOSHUA ROSENBAUM & JOSHUA PEARL)

Sheet Data & Forecasting 
A1: RHEINMETALL AG
A2: Input Page
A3: (EUR in millions, except per share data)
B7: General Information | G7: Reported Income Statement
B8: Company Name | D8: RHEINMETALL AG
B9: Ticker | D9: TTT | I9: Fiscal Year Ending (Dec 31) | K9: Forecasted Year
B10: Stock Exchange | D10: Xetra | I10: =D11-365 -> 45657 | J10: =D11 -> 46022 | K10: =J10+365 -> 46387
B11: Fiscal Year Ending | D11: 46022 | G11: Sales | I11: 7715 | J11: 9935 | K11: 14098
B12: Moody's Corporate Rating | D12: Baa1 | G12: COGS | I12: =3693+1844 -> 5537 | J12: =5252+2314 -> 7566 | K12: =10214.1+140.5 -> 10354.6
B13: S&P Corporate Rating | D13: NA | G13: Gross Profit | I13: =I11-SUM(I12:I12) -> 2178 | J13: =J11-SUM(J12:J12) -> 2369 | K13: =K11-SUM(K12:K12) -> 3743.4
B14: Predicted Beta | D14: 0.34 | G14: Other Income | I14: =132+178 -> 310 | J14: =521+273 -> 794 | K14: =J14*120% -> 952.8
B15: Marginal Tax Rate | D15: 0.25 | G15: SG&A & Other expenses | I15: =284+891+33+9 -> 1217 | J15: =406+1112+7-47 -> 1478 | K15: =J15*140% -> 2069.2
G16: EBIT | I16: =I13+I14-I15 -> 1271 | J16: =J13+J14-J15 -> 1685 | K16: =K13-K15+K14 -> 2627
B17: Selected Market Data | G17: Interest Expense | I17: =116-14 -> 102 | J17: =116-4 -> 112 | K17: 100
B18: Current Price | C18: 46110 | D18: 1379.5 | G18: Pre-tax Income | I18: =I16-SUM(I17:I17) -> 1169 | J18: =J16-SUM(J17:J17) -> 1573 | K18: =K16-SUM(K17:K17) -> 2527
B19: % of 52-week High | D19: =+IF(ISERROR(D18/D20),"NA",D18/D20) -> 0.68700199 | G19: Income Taxes | I19: 328 | J19: 396 | K19: =J19*160.23% -> 634.5108
B20: 52-week High Price | D20: 2008 | G20: Noncontrolling Interest | I20: =91 -> 91 | J20: =139 -> 139 | K20: =J20*160.23% -> 222.7197
B21: 52-week Low Price | D21: 933 | G21: Dicontinued Operations | I21: 32 | J21: 10 | K21: =J21*160.23% -> 16.023
B22: Dividend Per Share (MRQ) | D22: 2.86 | G22: Shareholders' Net Income | I22: =I18-SUM(I19:I21) -> 718 | J22: =J18-SUM(J19:J21) -> 1028 | K22: =K18-SUM(K19:K21) -> 1653.7465 | L22: <-- Didnt include discontinued operations from 2025 (-333) to match peers
B23: Used Share price (31 Dec 2025) | D23: 1561 | G23: Effective Tax Rate | I23: =+IF(ISERROR(I19/I18),"NA",I19/I18) -> 0.28058169 | J23: =+IF(ISERROR(J19/J18),"NA",J19/J18) -> 0.25174825 | K23: =+IF(ISERROR(K19/K18),"NA",K19/K18) -> 0.25109252
D24: =+O42 -> 0
B25: Fully Diluted Shares Outstanding | D25: 45.25 | G25: Weighted Avg. Diluted Shares | I25: 0 | J25: 0 | K25: 0
B26: Equity Value | D26: =+D25*D23 -> 70635.25 | G26: Diluted EPS | I26: =I22/D25 -> 15.867403 | J26: =J22/D25 -> 22.718232 | K26: =K22/D25 -> 36.546884
B28: Plus: Total Debt | D28: 2019 | G28: Other Information
B29: Plus: Preferred Stock | D29: 0 | G29: EBITDA | I29: 1881 | J29: 2185 | K29: 3220
B30: Less: Cash and Cash Equivalents | D30: -1650 | G30: Book Equity | I30: 4465 | J30: 5614
B31: Enterprise Value | D31: =SUM(D26:D30) -> 71004.25 | G31: Total Assets | I31: 14344 | J31: 16772
G32: Capex | I32: 732 | J32: 872 | K32: 1525
B34: Other Companies Basic Information | C34: Price | D34: Shares | E34: Market Cap | F34: EV | G34: Revenue 2024 | H34: Revenue 2025 | I34: Revenue 2026E | J34: EBITDA 2024 | K34: EBITDA 2025 | L34: EBITDA 2026E | M34: EBIT 2024 | N34: EBIT 2025 | O34: EBIT 2026E | P34: Net Income 2024 | Q34: Net Income 2025 | R34: Net Income 2026E | S34: Total Debt | T34: Net Debt | U34: EPS 2024 | V34: EPS 2025 | W34: EPS 2026E | X34: Book Equity 2024 | Y34: Book Equity 2025 | Z34: Total Assets 2024 | AA34: Total Assets 2025 | AB34: Capex | AC34: D&A | AD34: Tax Rate | AE34: Interest Expense
B35: Core Trading Reference Group
B36: BAE Systems (UK) GBP | C36: 17.14 | D36: 2910 | E36: =C36*D36 -> 49877.4 | F36: =E36+T36 -> 54811.4 | G36: 28335 | H36: 30662 | I36: 33155 | J36: 4112 | K36: 4495 | L36: 4643 | M36: 3015 | N36: 3322 | O36: 3628 | P36: 1956 | Q36: 2062 | R36: 2315 | S36: 10153 | T36: 4934 | U36: =P36/D36 -> 0.67216495 | V36: =Q36/D36 -> 0.70859107 | W36: =R36/D36 -> 0.79553265 | X36: 11616 | Y36: 11937 | Z36: 38142 | AA36: 37679 | AB36: 1103 | AC36: =K36-N36 -> 1173 | AD36: 0.22 | AE36: 504
B37: Thales (France) EUR | C37: 229.8 | D37: 205.523 | E37: =C37*D37 -> 47229.185 | F37: =E37+T37 -> 48867.685 | G37: 20577 | H37: 22136 | I37: 23799 | J37: 2898 | K37: 3827 | L37: 3740 | M37: 2419 | N37: 2740 | O37: 3008 | P37: 1420 | Q37: 1675 | R37: 1852 | S37: 6129.5 | T37: =S37-4491 -> 1638.5 | U37: =P37/D37 -> 6.9092024 | V37: =Q37/D37 -> 8.1499394 | W37: =R37/D37 -> 9.0111569 | X37: 7558.1 | Y37: 7968.7 | Z37: 39989.8 | AA37: 39155.4 | AB37: 756.7 | AC37: =K37-N37 -> 1087 | AD37: 0.204 | AE37: 285.1
B38: Leonardo (Italy) EUR | C38: 49.16 | D38: 575.94 | E38: =C38*D38 -> 28313.21 | F38: =E38+T38 -> 28956.21 | G38: 17763 | H38: 19503 | I38: 21258 | J38: 2219 | K38: 2429 | L38: 2752 | M38: 1525 | N38: 1752 | O38: 2047 | P38: 1074 | Q38: 1224 | R38: 1259 | S38: 4489 | T38: 643 | U38: =P38/D38 -> 1.8647776 | V38: =Q38/D38 -> 2.1252214 | W38: =R38/D38 -> 2.1859916 | X38: 8990 | Y38: 9560 | Z38: 33673 | AA38: 34509 | AB38: 1016 | AC38: =K38-N38 -> 677 | AD38: 0.191 | AE38: 96
B39: Saab (Sweden) SEK | C39: 537.6 | D39: 529.82 | E39: =C39*D39 -> 284831.23 | F39: =E39+T39 -> 290901.23 | G39: 63751 | H39: 79146 | I39: 95669 | J39: 8402 | K39: 11347 | L39: 13656 | M39: 5662 | N39: 8066 | O39: 10050 | P39: 4171 | Q39: 6314 | R39: 7689 | S39: 14709 | T39: 6070 | U39: =P39/D39 -> 7.872485 | V39: =Q39/D39 -> 11.917255 | W39: =R39/D39 -> 14.512476 | X39: 35503 | Y39: 43336 | Z39: 99823 | AA39: 124704 | AB39: 7222 | AC39: =K39-N39 -> 3281 | AD39: 0.206 | AE39: 200
B40: Kongsberg Gruppen (Norway) NOK | C40: 258.6 | D40: 879.56 | E40: =C40*D40 -> 227454.22 | F40: =E40+T40 -> 216522.22 | G40: 48872 | H40: 58599 | I40: 69690 | J40: 8028 | K40: 11024 | L40: 12619 | M40: 6507 | N40: 9296 | O40: 10588 | P40: 5126 | Q40: 7953 | R40: 9004 | S40: 4934 | T40: =S40-15866 -> -10932 | U40: =P40/D40 -> 5.827914 | V40: =Q40/D40 -> 9.042021 | W40: =R40/D40 -> 10.236937 | X40: 18677 | Y40: 22580 | Z40: 69414 | AA40: 82120 | AB40: 2856 | AC40: =K40-N40 -> 1728 | AD40: 0.2233 | AE40: 147
B42: Extendend Trading Reference Group
B43: Lockheed Martin (USD) | C43: 483.67 | D43: 235.385 | E43: =C43*D43 -> 113848.66 | F43: =E43+T43 -> 131427.66 | G43: 71043 | H43: 75048 | I43: 79080 | J43: 8572 | K43: 9418 | L43: 11271 | M43: 7013 | N43: 7731 | O43: 9611 | P43: 5336 | Q43: 5017 | R43: 6908 | S43: 21700 | T43: 17579 | U43: =P43/D43 -> 22.669244 | V43: =Q43/D43 -> 21.314017 | W43: =R43/D43 -> 29.347664 | X43: 6333 | Y43: 6721 | Z43: 55617 | AA43: 59840 | AB43: 1649 | AC43: =K43-N43 -> 1687 | AD43: 0.1528 | AE43: 1118
B44: Northrop Grumman (USD) | C44: 570.21 | D44: 143.1 | E44: =C44*D44 -> 81597.051 | F44: =E44+T44 -> 92356.051 | G44: 41033 | H44: 41954 | I44: 43870 | J44: 5740 | K44: 5983 | L44: 6182 | M44: 4370 | N44: 4511 | O44: 4643 | P44: 4174 | Q44: 4182 | R44: 3980 | S44: 17019 | T44: 10759 | U44: =P44/D44 -> 29.168414 | V44: =Q44/D44 -> 29.224319 | W44: =R44/D44 -> 27.812718 | X44: 15290 | Y44: 16674 | Z44: 49359 | AA44: 51377 | AB44: 1450 | AC44: =K44-N44 -> 1472 | AD44: 0.175 | AE44: 665
B45: General Dynamics (USD) | C45: 336.66 | D45: 273.928 | E45: =C45*D45 -> 92220.6 | F45: =E45+T45 -> 97900.6 | G45: 47716 | H45: 52550 | I45: 54736 | J45: 5682 | K45: 6280 | L45: 6631 | M45: 4796 | N45: 5356 | O45: 5677 | P45: 3782 | Q45: 4210 | R45: 4452 | S45: 9789 | T45: 5680 | U45: =P45/D45 -> 13.806548 | V45: =Q45/D45 -> 15.369002 | W45: =R45/D45 -> 16.252446 | X45: 22063 | Y45: 25622 | Z45: 55880 | AA45: 57249 | AB45: 1161 | AC45: =K45-N45 -> 924 | AD45: 0.323 | AE45: 402
B46: Safran (France) (EUR) | C46: 297.4 | D46: 417.029 | E46: =C46*D46 -> 124024.42 | F46: =E46+T46 -> 122560.42 | G46: 27317 | H46: 31329 | I46: 35586 | J46: 5413 | K46: 7015 | L46: 7678 | M46: 4119 | N46: 5197 | O46: 6139 | P46: -667 | Q46: 7177 | R46: 3956 | S46: 5325 | T46: =S46-6789 -> -1464 | U46: =P46/D46 -> -1.5994092 | V46: =Q46/D46 -> 17.209834 | W46: =R46/D46 -> 9.4861508 | X46: 10176 | Y46: 14839 | Z46: 55012 | AA46: 61814 | AB46: 1800 | AC46: =K46-N46 -> 1818 | AD46: 0.175 | AE46: 135
...

Sheet WACC
A1: RHEINMETALL AG
A2: Weighted Average Cost of Capital Analysis
A3: (EUR in millions)
A6: WACC Calculation | E6: Comparable Companies Unlevered Beta
A7: Target Capital Structure | F7: Predicted | G7: Market | H7: Market | I7: Debt/ | J7: Marginal | K7: Unlevered
A8: Debt-to-Total Capitalization | C8: ='Data & Forecasting '!D28/('Data & Forecasting '!D28+'Data & Forecasting '!D26) -> 0.027789152 | E8: Company | F8: Levered Beta (4) | G8: Value of Debt | H8: Value of Equity | I8: Equity | J8: Tax Rate | K8: Beta
A9: Equity-to-Total Capitalization | C9: =1-C8 -> 0.97221085 | E9: BAE Systems (UK) | F9: 0.6 | G9: ='Data & Forecasting '!S36 -> 10153 | H9: ='Data & Forecasting '!E36 -> 49877.4 | I9: =+IF(ISERROR(G9/H9),0,G9/H9) -> 0.20355913 | J9: ='Data & Forecasting '!AD36 -> 0.22 | K9: =+F9/(1+(I9)*(1-J9)) -> 0.51778768
E10: Thales (France) | F10: 0.67 | G10: ='Data & Forecasting '!S37 -> 6129.5 | H10: ='Data & Forecasting '!E37 -> 47229.185 | I10: =+IF(ISERROR(G10/H10),0,G10/H10) -> 0.12978204 | J10: ='Data & Forecasting '!AD37 -> 0.204 | K10: =+F10/(1+(I10)*(1-J10)) -> 0.60726552 | N10: • "realistical" beta choice for each firm
E11: Leonardo (Italy) | F11: 0.93 | G11: ='Data & Forecasting '!S38 -> 4489 | H11: ='Data & Forecasting '!E38 -> 28313.21 | I11: =+IF(ISERROR(G11/H11),0,G11/H11) -> 0.1585479 | J11: ='Data & Forecasting '!AD38 -> 0.191 | K11: =+F11/(1+(I11)*(1-J11)) -> 0.82427426 | M11: ---> | N11: • Changed it so that the wacc is believable
A12: Cost of Debt | E12: Saab (Sweden) | F12: 0.55 | G12: ='Data & Forecasting '!S39 -> 14709 | H12: ='Data & Forecasting '!E39 -> 284831.23 | I12: =+IF(ISERROR(G12/H12),0,G12/H12) -> 0.051641107 | J12: ='Data & Forecasting '!AD39 -> 0.206 | K12: =+F12/(1+(I12)*(1-J12)) -> 0.52833659
A13: Cost-of-Debt | C13: ='Data & Forecasting '!J17/'Data & Forecasting '!D28 -> 0.055473006 | E13: Kongsberg Gruppen (Norway) | F13: 0.89 | G13: ='Data & Forecasting '!S40 -> 4934 | H13: ='Data & Forecasting '!E40 -> 227454.22 | I13: =+IF(ISERROR(G13/H13),0,G13/H13) -> 0.021692278 | J13: ='Data & Forecasting '!AD40 -> 0.2233 | K13: =+F13/(1+(I13)*(1-J13)) -> 0.87525339
A14: Tax Rate | C14: ='Data & Forecasting '!J23 -> 0.25174825
A15: After-tax Cost of Debt | C15: =+C13*(1-C14) -> 0.041507774 | E15: Mean | F15: =AVERAGE(F9:F14) -> 0.728 | I15: =AVERAGE(I9:I14) -> 0.11304449 | K15: =AVERAGE(K9:K14) -> 0.67058349
E16: Median | F16: =MEDIAN(F9:F14) -> 0.67 | I16: =MEDIAN(I9:I14) -> 0.12978204 | K16: =MEDIAN(K9:K14) -> 0.60726552
A18: Cost of Equity | E18: RHEINMETALL AG Relevered Beta
A19: Risk-free Rate (1) | C19: 0.030914 | H19: Mean | I19: Target | J19: Target
A20: Market Risk Premium (2) | C20: 0.055 | H20: Unlevered | I20: Debt/ | J20: Marginal | K20: Relevered
A21: Levered Beta | C21: =K22 -> 0.68492568 | H21: Beta | I21: Equity | J21: Tax Rate | K21: Beta
A22: Size Premium (3) | C22: 0.005 | E22: Relevered Beta | H22: =K15 -> 0.67058349 | I22: =C8/C9 -> 0.028583462 | J22: =C14 -> 0.25174825 | K22: =+H22*(1+(I22)*(1-J22)) -> 0.68492568
A23: Cost of Equity | C23: =+C19+(C21*C20)+C22 -> 0.073584912
A26: WACC | C26: =(C8*C15)+(C9*C23) -> 0.072693516

Sheet Operating Forecast & Valuation
A1: RHEINMETALL AG
A2: Discounted Cash Flow Analysis
A3: (EUR in millions, fiscal year ending December 31)
A5: Operating Scenario | D5: Historical Period | G5: CAGR | I5: Projection Period | N5: CAGR
D6: 2022 | E6: 2023 | F6: 2024 | G6: ('22 - '24) | H6: 2025 | I6: 2026 | J6: 2027 | K6: 2028 | L6: 2029 | M6: 2030 | N6: ('25 - '30)
A7: Sales | D7: 6410 | E7: 7176 | F7: 9751 | G7: =+IF(ISERROR((F7/D7)^(1/($F$6-$D$6))-1),"-",(F7/D7)^(1/($F$6-$D$6))-1) -> 0.2333762 | H7: 9935 | I7: 14098 | J7: 19148 | K7: 25403 | L7: =K7*(1+L8) -> 31453.13 | M7: =L7*(1+M8) -> 36171.1 | N7: =+IF(ISERROR((M7/I7)^(1/($M$6-$I$6))-1),"-",(M7/I7)^(1/($M$6-$I$6))-1) -> 0.26561336
A8: % growth | D8: NA | E8: =+IF(ISERROR(E7/D7-1),0,E7/D7-1) -> 0.11950078 | F8: =+IF(ISERROR(F7/E7-1),0,F7/E7-1) -> 0.35883501 | H8: =+IF(ISERROR(H7/F7-1),0,H7/F7-1) -> 0.01886986 | I8: =+IF(ISERROR(I7/H7-1),0,I7/H7-1) -> 0.41902365 | J8: =+IF(ISERROR(J7/I7-1),0,J7/I7-1) -> 0.35820684 | K8: =+IF(ISERROR(K7/J7-1),0,K7/J7-1) -> 0.32666597 | L8: =K8-8.85% -> 0.23816597 | M8: 0.15
A9: EBITDA | D9: 980 | E9: 1226 | F9: 1881 | G9: =+IF(ISERROR((F9/D9)^(1/($F$6-$D$6))-1),"-",(F9/D9)^(1/($F$6-$D$6))-1) -> 0.3854197 | H9: 2185 | I9: 3220 | J9: 4537 | K9: 6217 | L9: =L10*L7 -> 7800.3763 | M9: =M10*M7 -> 9042.7749 | N9: =+IF(ISERROR((M9/I9)^(1/($M$6-$I$6))-1),"-",(M9/I9)^(1/($M$6-$I$6))-1) -> 0.29452804
A10: % margin | D10: =+IF(ISERROR(D9/D7),0,D9/D7) -> 0.15288612 | E10: =+IF(ISERROR(E9/E7),0,E9/E7) -> 0.17084727 | F10: =+IF(ISERROR(F9/F7),0,F9/F7) -> 0.19290329 | H10: =+IF(ISERROR(H9/H7),0,H9/H7) -> 0.21992954 | I10: =+IF(ISERROR(I9/I7),0,I9/I7) -> 0.22840119 | J10: =+IF(ISERROR(J9/J7),0,J9/J7) -> 0.23694381 | K10: =+IF(ISERROR(K9/K7),0,K9/K7) -> 0.24473487 | L10: 0.248 | M10: 0.25 | P10: • 2026–2028 based on analyst consensus
A11: Depreciation & Amortization | D11: =D9-D12 -> 249 | E11: =E9-E12 -> 329 | F11: =F9-F12 -> 536 | H11: =H9-H12 -> 501 | I11: =I9-I12 -> 593 | J11: =J9-J12 -> 755 | K11: =K9-K12 -> 1049 | L11: =L9-L12 -> 1565.1843 | M11: =M9-M12 -> 1498.1926 | O11: ---> | P11: • 2029–2030 gradually normalized
A12: EBIT | D12: 731 | E12: 897 | F12: 1345 | G12: =+IF(ISERROR((F12/D12)^(1/($F$6-$D$6))-1),"-",(F12/D12)^(1/($F$6-$D$6))-1) -> 0.35644583 | H12: 1684 | I12: 2627 | J12: 3782 | K12: 5168 | L12: =K12*(1+L13) -> 6235.192 | M12: =L12*(1+M13) -> 7544.5823 | N12: =+IF(ISERROR((M12/I12)^(1/($M$6-$I$6))-1),"-",(M12/I12)^(1/($M$6-$I$6))-1) -> 0.30179855 | P12: • Assumes sustained elevated defense spending, but partial margin stabilization
A13: % margin | D13: =+IF(ISERROR(D12/D7),0,D12/D7) -> 0.11404056 | E13: =+IF(ISERROR(E12/E7),0,E12/E7) -> 0.125 | F13: =+IF(ISERROR(F12/F7),0,F12/F7) -> 0.13793457 | H13: =+IF(ISERROR(H12/H7),0,H12/H7) -> 0.16950176 | I13: =+IF(ISERROR(I12/I7),0,I12/I7) -> 0.18633849 | J13: =+IF(ISERROR(J12/J7),0,J12/J7) -> 0.1975141 | K13: =+IF(ISERROR(K12/K7),0,K12/K7) -> 0.20344054 | L13: 0.2065 | M13: 0.21
A14: Taxes | D14: =+D12*D58 -> 188.4518 | E14: =+E12*E58 -> 203.619 | F14: =+F12*F58 -> 377.38238 | H14: =+H12*H58 -> 423.94406 | I14: =+I12*I58 -> 659.62005 | J14: =+J12*J58 -> 949.63191 | K14: =+K12*K58 -> 1297.6461 | L14: =+L12*L58 -> 1565.6101 | M14: =+M12*M58 -> 1894.3882
A15: NOPAT | D15: =+D12-D14 -> 542.5482 | E15: =+E12-E14 -> 693.381 | F15: =+F12-F14 -> 967.61762 | G15: =+IF(ISERROR((F15/D15)^(1/($F$6-$D$6))-1),"-",(F15/D15)^(1/($F$6-$D$6))-1) -> 0.33546565 | H15: =+H12-H14 -> 1260.0559 | I15: =+I12-I14 -> 1967.3799 | J15: =+J12-J14 -> 2832.3681 | K15: =+K12-K14 -> 3870.3539 | L15: =+L12-L14 -> 4669.5819 | M15: =+M12-M14 -> 5650.1941 | N15: =+IF(ISERROR((M15/I15)^(1/($M$6-$I$6))-1),"-",(M15/I15)^(1/($M$6-$I$6))-1) -> 0.30179855
A17: Plus: Depreciation & Amortization | D17: =D11 -> 249 | E17: =E11 -> 329 | F17: =F11 -> 536 | H17: =H11 -> 501 | I17: =I11 -> 593 | J17: =J11 -> 755 | K17: =K11 -> 1049 | L17: =L11 -> 1565.1843 | M17: =M11 -> 1498.1926
A18: Less: Capital Expenditures | D18: -349 | E18: -398 | F18: -732 | H18: -872 | I18: -1525 | J18: -1698 | K18: -1914 | L18: -2154.828 | M18: -2453.5902
A19: Less: Inc./(Dec.) in Net Working Capital | D19: NA | E19: =-1633+1513 -> -120 | F19: =-1449+1633 -> 184 | H19: =-1830+1449 -> -381 | I19: =-(I7-H7)*0.1 -> -416.3 | J19: =-(J7-I7)*0.11 -> -555.5 | K19: =-(K7-J7)*0.12 -> -750.6 | L19: =-(L7-K7)*0.13 -> -786.51692 | M19: =-(M7-L7)*0.14 -> -660.51573
A21: Unlevered Free Cash Flow | I21: =+I15+SUM(I17:I19) -> 619.07995 | J21: =+J15+SUM(J17:J19) -> 1333.8681 | K21: =+K15+SUM(K17:K19) -> 2254.7539 | L21: =+L15+SUM(L17:L19) -> 3293.4213 | M21: =+M15+SUM(M17:M19) -> 4034.2808
A22: WACC | D22: =WACC!C26 -> 0.072693516
A23: Discount Period | I23: =IF($D$5="Y",I6-$I$6-0.5,I6-$I$6) -> 0 | J23: =IF($D$5="Y",J6-$I$6-0.5,J6-$I$6) -> 1 | K23: =IF($D$5="Y",K6-$I$6-0.5,K6-$I$6) -> 2 | L23: =IF($D$5="Y",L6-$I$6-0.5,L6-$I$6) -> 3 | M23: =IF($D$5="Y",M6-$I$6-0.5,M6-$I$6) -> 4
A24: Discount Factor | I24: =1/((1+$D$22)^(I23)) -> 1 | J24: =1/((1+$D$22)^(J23)) -> 0.93223273 | K24: =1/((1+$D$22)^(K23)) -> 0.86905785 | L24: =1/((1+$D$22)^(L23)) -> 0.81016417 | M24: =1/((1+$D$22)^(M23)) -> 0.75526155
A25: Present Value of Free Cash Flow | I25: =+I21*I24 -> 619.07995 | J25: =+J21*J24 -> 1243.4755 | K25: =+K21*K24 -> 1959.5115 | L25: =+L21*L24 -> 2668.2119 | M25: =+M21*M24 -> 3046.9372
A28: Enterprise Value | F28: Implied Equity Value and Share Price | K28: Implied Perpetuity Growth Rate
A29: Cumulative Present Value of FCF | D29: =+SUM(I25:M25) -> 9537.2161 | F29: Enterprise Value | I29: =D39 -> 85939.21 | K29: ="Terminal Year Free Cash Flow ("&M6&"E)" -> Terminal Year Free Cash Flow (2030E) | N29: =+M21 -> 4034.2808
F30: Less: Total Debt | I30: =-'Data & Forecasting '!D28 -> -2019 | K30: WACC | N30: =+D22 -> 0.072693516
A31: Terminal Value | F31: Less: Preferred Stock | I31: 0 | K31: =+A31 -> Terminal Value | N31: =+D34 -> 108513.3
A32: ="Terminal Year EBITDA ("&M6&"E)" -> Terminal Year EBITDA (2030E) | D32: =+M9 -> 9042.7749 | F32: Less: Noncontrolling Interest | I32: =-'Data & Forecasting '!J20 -> -139
A33: Exit Multiple | D33: 12 | F33: Plus: Cash and Cash Equivalents | I33: =-'Data & Forecasting '!D30 -> 1650 | K33: Implied Perpetuity Growth Rate | N33: =+IF(ISERROR(IF(C5="Y",((D34*D22)-M21*(1+D22)^0.5)/(D34+M21*(1+D22)^0.5),((N31*N30)-N29)/(N31+N29))),"- %",IF(C5="Y",((D34*D22)-M21*(1+D22)^0.5)/(D34+M21*(1+D22)^0.5),((N31*N30)-N29)/(N31+N29))) -> 0.034242695
A34: Terminal Value | D34: =+D32*D33 -> 108513.3
A35: Discount Factor | D35: =1/((1+$D$22)^(M6-H6)) -> 0.70407954 | F35: Implied Equity Value | I35: =+I29+SUM(I30:I33) -> 85431.21 | K35: Implied EV/EBITDA
A36: Present Value of Terminal Value | D36: =+D34*D35 -> 76401.993 | K36: =+F29 -> Enterprise Value | N36: =D39 -> 85939.21
A37: % of Enterprise Value | D37: =+IF(ISERROR(D36/D39),"- %",D36/D39) -> 0.88902369 | F37: Fully Diluted Shares Outstanding | I37: ='Data & Forecasting '!D25 -> 45.25 | K37: LTM 12/31/2030 EBITDA | N37: =M9 -> 9042.7749
F38: Market Share Price (Dec 31 2025) | I38: ='Data & Forecasting '!D23 -> 1561
A39: Enterprise Value | D39: =+D36+D29 -> 85939.21 | F39: Implied Share Price | I39: =+IF(ISERROR(I35/I37),"NA",I35/I37) -> 1887.9825 | K39: Implied EV/EBITDA | N39: =+IF(ISERROR(N36/N37),"- x",N36/N37) -> 9.5036325
F40: Upside / Downside | I40: =(I39-I38)/I38 -> 0.20946991
B42: Enterprise Value | I42: Implied Perpetuity Growth Rate
C43: Exit Multiple | J43: Exit Multiple
B44: =+D39 -> 85939.21 | C44: =+D44-0.5 -> 11 | D44: =+E44-0.5 -> 11.5 | E44: 12 | F44: =+E44+0.5 -> 12.5 | G44: =+F44+0.5 -> 13 | I44: =+N33 -> 0.034242695 | J44: =+K44-0.5 -> 11 | K44: =+L44-0.5 -> 11.5 | L44: 12 | M44: =+L44+0.5 -> 12.5 | N44: =+M44+0.5 -> 13
A45: WACC | B45: =+B46-0.005 -> 0.065 | C45: 82323.488 | D45: 85623.562 | E45: 88923.636 | F45: 92223.71 | G45: 95523.784 | H45: WACC | I45: =+I46-0.005 -> 0.065 | J45: 0.023489762 | K45: 0.025227154 | L45: 0.026824954 | M45: 0.028299334 | N45: 0.029664063
B46: =+B47-0.005 -> 0.07 | C46: 80522.33 | D46: 83746.017 | E46: 86969.704 | F46: 90193.391 | G46: 93417.077 | I46: =+I47-0.005 -> 0.07 | J46: 0.028294878 | K46: 0.030040427 | L46: 0.031645728 | M46: 0.03312703 | N46: 0.034498167
...

Sheet Benchmarking Analysis
A1: RHEINMETALL AG
A2: Benchmarking Analysis – Financial Statistics and Ratios
C6: Market Valuation | F6: LTM Financial Statistics | K6: LTM Profitability Margins | O6: Growth Rates
M7: Net | O7: Sales | Q7: EBITDA | S7: EPS
C8: Equity | D8: Enterprise | I8: Net | K8: EBITDA | L8: EBIT | M8: Income | O8: Hist. | P8: Est. | Q8: Hist. | R8: Est. | S8: Hist. | T8: Est.
A9: Company | B9: Currency | C9: Value | D9: Value | F9: Sales | G9: EBITDA | H9: EBIT | I9: Income | K9: (%) | L9: (%) | M9: (%) | O9: 1-year | P9: 1-year | Q9: 1-year | R9: 1-year | S9: 1-year | T9: 1-year
A11: RHEINMETALL AG | B11: EUR | C11: ='Data & Forecasting '!D26*1000000 -> 70635250000 | D11: ='Data & Forecasting '!D31*1000000 -> 71004250000 | F11: ='Data & Forecasting '!J11*1000000 -> 9935000000 | G11: ='Data & Forecasting '!J29*1000000 -> 2185000000 | H11: ='Data & Forecasting '!J16*1000000 -> 1685000000 | I11: ='Data & Forecasting '!J22*1000000 -> 1028000000 | K11: =G11/F11 -> 0.21992954 | L11: =H11/F11 -> 0.16960242 | M11: =I11/F11 -> 0.10347257 | O11: =('Data & Forecasting '!J11-'Data & Forecasting '!I11)/'Data & Forecasting '!I11 -> 0.28775113 | P11: =('Data & Forecasting '!K11-'Data & Forecasting '!J11)/'Data & Forecasting '!J11 -> 0.41902365 | Q11: =('Data & Forecasting '!J29-'Data & Forecasting '!I29)/'Data & Forecasting '!I29 -> 0.16161616 | R11: =('Data & Forecasting '!K29-'Data & Forecasting '!J29)/'Data & Forecasting '!J29 -> 0.47368421 | S11: =('Data & Forecasting '!J26-'Data & Forecasting '!I26)/'Data & Forecasting '!I26 -> 0.43175487 | T11: =('Data & Forecasting '!K26-'Data & Forecasting '!J26)/'Data & Forecasting '!J26 -> 0.60870282
A13: Core Trading Reference Group
A14: BAE Systems (UK) | B14: GBP | C14: ='Data & Forecasting '!E36*1000000 -> 49877400000 | D14: =C14+'Data & Forecasting '!T36*1000000 -> 54811400000 | F14: ='Data & Forecasting '!H36*1000000 -> 30662000000 | G14: ='Data & Forecasting '!K36*1000000 -> 4495000000 | H14: ='Data & Forecasting '!N36*1000000 -> 3322000000 | I14: ='Data & Forecasting '!Q36*1000000 -> 2062000000 | K14: =G14/F14 -> 0.1465984 | L14: =H14/F14 -> 0.10834257 | M14: =I14/F14 -> 0.067249364 | O14: =('Data & Forecasting '!H36-'Data & Forecasting '!G36)/'Data & Forecasting '!G36 -> 0.082124581 | P14: =('Data & Forecasting '!I36-'Data & Forecasting '!H36)/'Data & Forecasting '!H36 -> 0.081305851 | Q14: =('Data & Forecasting '!K36-'Data & Forecasting '!J36)/'Data & Forecasting '!J36 -> 0.093142023 | R14: =('Data & Forecasting '!L36-'Data & Forecasting '!K36)/'Data & Forecasting '!K36 -> 0.032925473 | S14: =('Data & Forecasting '!V36-'Data & Forecasting '!U36)/'Data & Forecasting '!U36 -> 0.054192229 | T14: =('Data & Forecasting '!W36-'Data & Forecasting '!V36)/'Data & Forecasting '!V36 -> 0.12269641
A15: Thales (France) | B15: EUR | C15: ='Data & Forecasting '!E37*1000000 -> 47229185400 | D15: =C15+'Data & Forecasting '!T37*1000000 -> 48867685400 | F15: ='Data & Forecasting '!H37*1000000 -> 22136000000 | G15: ='Data & Forecasting '!K37*1000000 -> 3827000000 | H15: ='Data & Forecasting '!N37*1000000 -> 2740000000 | I15: ='Data & Forecasting '!Q37*1000000 -> 1675000000 | K15: =G15/F15 -> 0.1728858 | L15: =H15/F15 -> 0.12378027 | M15: =I15/F15 -> 0.075668594 | O15: =('Data & Forecasting '!H37-'Data & Forecasting '!G37)/'Data & Forecasting '!G37 -> 0.075764203 | P15: =('Data & Forecasting '!I37-'Data & Forecasting '!H37)/'Data & Forecasting '!H37 -> 0.075126491 | Q15: =('Data & Forecasting '!K37-'Data & Forecasting '!J37)/'Data & Forecasting '!J37 -> 0.32056591 | R15: =('Data & Forecasting '!L37-'Data & Forecasting '!K37)/'Data & Forecasting '!K37 -> -0.022733211 | S15: =('Data & Forecasting '!V37-'Data & Forecasting '!U37)/'Data & Forecasting '!U37 -> 0.17957746 | T15: =('Data & Forecasting '!W37-'Data & Forecasting '!V37)/'Data & Forecasting '!V37 -> 0.10567164
A16: Leonardo (Italy) | B16: EUR | C16: ='Data & Forecasting '!E38*1000000 -> 28313210400 | D16: ='Benchmarking Analysis'!C16+'Data & Forecasting '!T38*1000000 -> 28956210400 | F16: ='Data & Forecasting '!H38*1000000 -> 19503000000 | G16: ='Data & Forecasting '!K38*1000000 -> 2429000000 | H16: ='Data & Forecasting '!N38*1000000 -> 1752000000 | I16: ='Data & Forecasting '!Q38*1000000 -> 1224000000 | K16: =G16/F16 -> 0.12454494 | L16: =H16/F16 -> 0.089832333 | M16: =I16/F16 -> 0.062759575 | O16: =('Data & Forecasting '!H38-'Data & Forecasting '!G38)/'Data & Forecasting '!G38 -> 0.097956426 | P16: =('Data & Forecasting '!I38-'Data & Forecasting '!H38)/'Data & Forecasting '!H38 -> 0.089986156 | Q16: =('Data & Forecasting '!K38-'Data & Forecasting '!J38)/'Data & Forecasting '!J38 -> 0.094637224 | R16: =('Data & Forecasting '!L38-'Data & Forecasting '!K38)/'Data & Forecasting '!K38 -> 0.13297653 | S16: =('Data & Forecasting '!V38-'Data & Forecasting '!U38)/'Data & Forecasting '!U38 -> 0.1396648 | T16: =('Data & Forecasting '!W38-'Data & Forecasting '!V38)/'Data & Forecasting '!V38 -> 0.028594771
A17: Saab (Sweden) | B17: SEK | C17: ='Data & Forecasting '!E39*1000000 -> 284831232000 | D17: =C17+'Data & Forecasting '!T39*1000000 -> 290901232000 | F17: ='Data & Forecasting '!H39*1000000 -> 79146000000 | G17: ='Data & Forecasting '!K39*1000000 -> 11347000000 | H17: ='Data & Forecasting '!N39*1000000 -> 8066000000 | I17: ='Data & Forecasting '!Q39*1000000 -> 6314000000 | K17: =G17/F17 -> 0.14336795 | L17: =H17/F17 -> 0.10191292 | M17: =I17/F17 -> 0.079776615 | O17: =('Data & Forecasting '!H39-'Data & Forecasting '!G39)/'Data & Forecasting '!G39 -> 0.24148641 | P17: =('Data & Forecasting '!I39-'Data & Forecasting '!H39)/'Data & Forecasting '!H39 -> 0.20876608 | Q17: =('Data & Forecasting '!K39-'Data & Forecasting '!J39)/'Data & Forecasting '!J39 -> 0.35051178 | R17: =('Data & Forecasting '!L39-'Data & Forecasting '!K39)/'Data & Forecasting '!K39 -> 0.20348991 | S17: =('Data & Forecasting '!V39-'Data & Forecasting '!U39)/'Data & Forecasting '!U39 -> 0.51378566 | T17: =('Data & Forecasting '!W39-'Data & Forecasting '!V39)/'Data & Forecasting '!V39 -> 0.21777003
A18: Kongsberg Gruppen (Norway) | B18: NOK | C18: ='Data & Forecasting '!E40*1000000 -> 227454216000 | D18: =C18+'Data & Forecasting '!T40*1000000 -> 216522216000 | F18: ='Data & Forecasting '!H40*1000000 -> 58599000000 | G18: ='Data & Forecasting '!K40*1000000 -> 11024000000 | H18: ='Data & Forecasting '!N40*1000000 -> 9296000000 | I18: ='Data & Forecasting '!Q40*1000000 -> 7953000000 | K18: =G18/F18 -> 0.18812608 | L18: =H18/F18 -> 0.15863752 | M18: =I18/F18 -> 0.13571904 | O18: =('Data & Forecasting '!H40-'Data & Forecasting '!G40)/'Data & Forecasting '!G40 -> 0.19903012 | P18: =('Data & Forecasting '!I40-'Data & Forecasting '!H40)/'Data & Forecasting '!H40 -> 0.18926944 | Q18: =('Data & Forecasting '!K40-'Data & Forecasting '!J40)/'Data & Forecasting '!J40 -> 0.37319382 | R18: =('Data & Forecasting '!L40-'Data & Forecasting '!K40)/'Data & Forecasting '!K40 -> 0.14468433 | S18: =('Data & Forecasting '!V40-'Data & Forecasting '!U40)/'Data & Forecasting '!U40 -> 0.55150215 | T18: =('Data & Forecasting '!W40-'Data & Forecasting '!V40)/'Data & Forecasting '!V40 -> 0.13215139
A20: Mean | K20: =IF(ISERROR(AVERAGE(K14:K18)),"NA",AVERAGE(K14:K18)) -> 0.15510463 | L20: =IF(ISERROR(AVERAGE(L14:L18)),"NA",AVERAGE(L14:L18)) -> 0.11650112 | M20: =IF(ISERROR(AVERAGE(M14:M18)),"NA",AVERAGE(M14:M18)) -> 0.084234638 | O20: =+AVERAGE(O14:O18) -> 0.13927235 | P20: =+AVERAGE(P14:P18) -> 0.1288908 | Q20: =+AVERAGE(Q14:Q18) -> 0.24641015 | R20: =+AVERAGE(R14:R18) -> 0.098268606 | S20: =+AVERAGE(S14:S18) -> 0.28774446 | T20: =+AVERAGE(T14:T18) -> 0.12137685
A21: Median | K21: =IF(ISERROR(MEDIAN(K14:K18)),"NA",MEDIAN(K14:K18)) -> 0.1465984 | L21: =IF(ISERROR(MEDIAN(L14:L18)),"NA",MEDIAN(L14:L18)) -> 0.10834257 | M21: =IF(ISERROR(MEDIAN(M14:M18)),"NA",MEDIAN(M14:M18)) -> 0.075668594 | O21: =MEDIAN(O14:O18) -> 0.097956426 | P21: =MEDIAN(P14:P18) -> 0.089986156 | Q21: =MEDIAN(Q14:Q18) -> 0.32056591 | R21: =MEDIAN(R14:R18) -> 0.13297653 | S21: =MEDIAN(S14:S18) -> 0.17957746 | T21: =MEDIAN(T14:T18) -> 0.12269641
A23: Extendend Trading Reference Group
A24: Lockheed Martin (US) | B24: USD | C24: ='Data & Forecasting '!E43*1000000 -> 113848662950 | D24: ='Data & Forecasting '!F43*1000000 -> 131427662950 | F24: ='Data & Forecasting '!H43*1000000 -> 75048000000 | G24: ='Data & Forecasting '!K43*1000000 -> 9418000000 | H24: ='Data & Forecasting '!N43*1000000 -> 7731000000 | I24: ='Data & Forecasting '!Q43*1000000 -> 5017000000 | K24: =G24/F24 -> 0.12549302 | L24: =H24/F24 -> 0.10301407 | M24: =I24/F24 -> 0.066850549 | O24: =('Data & Forecasting '!H43-'Data & Forecasting '!G43)/'Data & Forecasting '!G43 -> 0.056374309 | P24: =('Data & Forecasting '!I43-'Data & Forecasting '!H43)/'Data & Forecasting '!H43 -> 0.053725616 | Q24: =('Data & Forecasting '!K43-'Data & Forecasting '!J43)/'Data & Forecasting '!J43 -> 0.09869342 | R24: =('Data & Forecasting '!L43-'Data & Forecasting '!K43)/'Data & Forecasting '!K43 -> 0.1967509 | S24: =('Data & Forecasting '!V43-'Data & Forecasting '!U43)/'Data & Forecasting '!U43 -> -0.059782609 | T24: =('Data & Forecasting '!W43-'Data & Forecasting '!V43)/'Data & Forecasting '!V43 -> 0.37691848
A25: Northrop Grumman (US) | B25: USD | C25: ='Data & Forecasting '!E44*1000000 -> 81597051000 | D25: ='Data & Forecasting '!F44*1000000 -> 92356051000 | F25: ='Data & Forecasting '!H44*1000000 -> 41954000000 | G25: ='Data & Forecasting '!K44*1000000 -> 5983000000 | H25: ='Data & Forecasting '!N44*1000000 -> 4511000000 | I25: ='Data & Forecasting '!Q44*1000000 -> 4182000000 | K25: =G25/F25 -> 0.14260857 | L25: =H25/F25 -> 0.10752252 | M25: =I25/F25 -> 0.099680603 | O25: =('Data & Forecasting '!H44-'Data & Forecasting '!G44)/'Data & Forecasting '!G44 -> 0.022445349 | P25: =('Data & Forecasting '!I44-'Data & Forecasting '!H44)/'Data & Forecasting '!H44 -> 0.045669066 | Q25: =('Data & Forecasting '!K44-'Data & Forecasting '!J44)/'Data & Forecasting '!J44 -> 0.042334495 | R25: =('Data & Forecasting '!L44-'Data & Forecasting '!K44)/'Data & Forecasting '!K44 -> 0.033260906 | S25: =('Data & Forecasting '!V44-'Data & Forecasting '!U44)/'Data & Forecasting '!U44 -> 0.0019166267 | T25: =('Data & Forecasting '!W44-'Data & Forecasting '!V44)/'Data & Forecasting '!V44 -> -0.048302248
A26: General Dynamics (US) | B26: USD | C26: ='Data & Forecasting '!E45*1000000 -> 9.22206e+10 | D26: ='Data & Forecasting '!F45*1000000 -> 9.79006e+10 | F26: ='Data & Forecasting '!H45*1000000 -> 52550000000 | G26: ='Data & Forecasting '!K45*1000000 -> 6280000000 | H26: ='Data & Forecasting '!N45*1000000 -> 5356000000 | I26: ='Data & Forecasting '!Q45*1000000 -> 4210000000 | K26: =G26/F26 -> 0.11950523 | L26: =H26/F26 -> 0.10192198 | M26: =I26/F26 -> 0.080114177 | O26: =('Data & Forecasting '!H45-'Data & Forecasting '!G45)/'Data & Forecasting '!G45 -> 0.10130774 | P26: =('Data & Forecasting '!I45-'Data & Forecasting '!H45)/'Data & Forecasting '!H45 -> 0.041598478 | Q26: =('Data & Forecasting '!K45-'Data & Forecasting '!J45)/'Data & Forecasting '!J45 -> 0.10524463 | R26: =('Data & Forecasting '!L45-'Data & Forecasting '!K45)/'Data & Forecasting '!K45 -> 0.05589172 | S26: =('Data & Forecasting '!V45-'Data & Forecasting '!U45)/'Data & Forecasting '!U45 -> 0.11316764 | T26: =('Data & Forecasting '!W45-'Data & Forecasting '!V45)/'Data & Forecasting '!V45 -> 0.057482185
A27: Safran (France) | B27: EUR | C27: ='Data & Forecasting '!E46*1000000 -> 1.2402442e+11 | D27: ='Data & Forecasting '!F46*1000000 -> 1.2256042e+11 | F27: ='Data & Forecasting '!H46*1000000 -> 31329000000 | G27: ='Data & Forecasting '!K46*1000000 -> 7015000000 | H27: ='Data & Forecasting '!N46*1000000 -> 5197000000 | I27: ='Data & Forecasting '!Q46*1000000 -> 7177000000 | K27: =G27/F27 -> 0.22391395 | L27: =H27/F27 -> 0.16588464 | M27: =I27/F27 -> 0.22908487 | O27: =('Data & Forecasting '!H46-'Data & Forecasting '!G46)/'Data & Forecasting '!G46 -> 0.14686825 | P27: =('Data & Forecasting '!I46-'Data & Forecasting '!H46)/'Data & Forecasting '!H46 -> 0.13588049 | Q27: =('Data & Forecasting '!K46-'Data & Forecasting '!J46)/'Data & Forecasting '!J46 -> 0.29595418 | R27: =('Data & Forecasting '!L46-'Data & Forecasting '!K46)/'Data & Forecasting '!K46 -> 0.094511761 | S27: =('Data & Forecasting '!V46-'Data & Forecasting '!U46)/'Data & Forecasting '!U46 -> -11.76012 | T27: =('Data & Forecasting '!W46-'Data & Forecasting '!V46)/'Data & Forecasting '!V46 -> -0.44879476
A28: Rolls-Royce (UK) | B28: GBP | C28: ='Data & Forecasting '!E47*1000000 -> 1.3264536e+11 | D28: ='Data & Forecasting '!F47*1000000 -> 1.3088336e+11 | F28: ='Data & Forecasting '!H47*1000000 -> 20059000000 | G28: ='Data & Forecasting '!K47*1000000 -> 4362000000 | H28: ='Data & Forecasting '!N47*1000000 -> 3462000000 | I28: ='Data & Forecasting '!Q47*1000000 -> 5841000000 | K28: =G28/F28 -> 0.2174585 | L28: =H28/F28 -> 0.17259086 | M28: =I28/F28 -> 0.29119099 | O28: =('Data & Forecasting '!H47-'Data & Forecasting '!G47)/'Data & Forecasting '!G47 -> 0.12387943 | P28: =('Data & Forecasting '!I47-'Data & Forecasting '!H47)/'Data & Forecasting '!H47 -> 0.11670572 | Q28: =('Data & Forecasting '!K47-'Data & Forecasting '!J47)/'Data & Forecasting '!J47 -> 0.31504371 | R28: =('Data & Forecasting '!L47-'Data & Forecasting '!K47)/'Data & Forecasting '!K47 -> 0.10797799 | S28: =('Data & Forecasting '!V47-'Data & Forecasting '!U47)/'Data & Forecasting '!U47 -> 1.3169377 | T28: =('Data & Forecasting '!W47-'Data & Forecasting '!V47)/'Data & Forecasting '!V47 -> -0.4711522
A30: Mean | K30: =+AVERAGE(K24:K28) -> 0.16579585 | L30: =+AVERAGE(L24:L28) -> 0.13018682 | M30: =+AVERAGE(M24:M28) -> 0.15338424 | O30: =+AVERAGE(O24:O28) -> 0.090175014 | P30: =+AVERAGE(P24:P28) -> 0.078715874 | Q30: =+AVERAGE(Q24:Q28) -> 0.17145409 | R30: =+AVERAGE(R24:R28) -> 0.097678656 | S30: =+AVERAGE(S24:S28) -> -2.0775761 | T30: =+AVERAGE(T24:T28) -> -0.10676971
A31: Median | K31: =MEDIAN(K24:K28) -> 0.14260857 | L31: =MEDIAN(L24:L28) -> 0.10752252 | M31: =MEDIAN(M24:M28) -> 0.099680603 | O31: =MEDIAN(O24:O28) -> 0.10130774 | P31: =MEDIAN(P24:P28) -> 0.053725616 | Q31: =MEDIAN(Q24:Q28) -> 0.10524463 | R31: =MEDIAN(R24:R28) -> 0.094511761 | S31: =MEDIAN(S24:S28) -> 0.0019166267 | T31: =MEDIAN(T24:T28) -> -0.048302248
A33: Overall
A35: Mean | K35: =+AVERAGE(K14:K18,K24:K28) -> 0.16045024 | L35: =+AVERAGE(L14:L18,L24:L28) -> 0.12334397 | M35: =+AVERAGE(M14:M18,M24:M28) -> 0.11880944 | O35: =+AVERAGE(O14:O18,O24:O28) -> 0.11472368 | P35: =+AVERAGE(P14:P18,P24:P28) -> 0.10380334 | Q35: =+AVERAGE(Q14:Q18,Q24:Q28) -> 0.20893212 | R35: =+AVERAGE(R14:R18,R24:R28) -> 0.097973631 | S35: =+AVERAGE(S14:S18,S24:S28) -> -0.89491583 | T35: =+AVERAGE(T14:T18,T24:T28) -> 0.0073035702
A36: Median | K36: =+MEDIAN(K14:K18,K24:K28) -> 0.14498317 | L36: =+MEDIAN(L14:L18,L24:L28) -> 0.10793255 | M36: =+MEDIAN(M14:M18,M24:M28) -> 0.079945396 | O36: =+MEDIAN(O14:O18,O24:O28) -> 0.099632082 | P36: =+MEDIAN(P14:P18,P24:P28) -> 0.085646003 | Q36: =+MEDIAN(Q14:Q18,Q24:Q28) -> 0.20059941 | R36: =+MEDIAN(R14:R18,R24:R28) -> 0.10124488 | S36: =+MEDIAN(S14:S18,S24:S28) -> 0.12641622 | T36: =+MEDIAN(T14:T18,T24:T28) -> 0.081576914
A38: High | K38: =+MAX(K14:K18,K24:K28) -> 0.22391395 | L38: =+MAX(L14:L18,L24:L28) -> 0.17259086 | M38: =+MAX(M14:M18,M24:M28) -> 0.29119099 | O38: =+MAX(O14:O18,O24:O28) -> 0.24148641 | P38: =+MAX(P14:P18,P24:P28) -> 0.20876608 | Q38: =+MAX(Q14:Q18,Q24:Q28) -> 0.37319382 | R38: =+MAX(R14:R18,R24:R28) -> 0.20348991 | S38: =+MAX(S14:S18,S24:S28) -> 1.3169377 | T38: =+MAX(T14:T18,T24:T28) -> 0.37691848
A39: Low | K39: =+MIN(K14:K18,K24:K28) -> 0.11950523 | L39: =+MIN(L14:L18,L24:L28) -> 0.089832333 | M39: =+MIN(M14:M18,M24:M28) -> 0.062759575 | O39: =+MIN(O14:O18,O24:O28) -> 0.022445349 | P39: =+MIN(P14:P18,P24:P28) -> 0.041598478 | Q39: =+MIN(Q14:Q18,Q24:Q28) -> 0.042334495 | R39: =+MIN(R14:R18,R24:R28) -> -0.022733211 | S39: =+MIN(S14:S18,S24:S28) -> -11.76012 | T39: =+MIN(T14:T18,T24:T28) -> -0.4711522

Sheet Benchmarking Analysis (x) LTM
A1: RHEINMETALL AG
A2: Benchmarking Analysis – Multiples Analysis LTM
C6: General | F6: Return on Investment | J6: LTM Leverage Ratios | N6: LTM Coverage Ratios | R6: Credit Ratings | U6: LTM Valuation Multiples
J7: Debt / | K7: Debt / | L7: Net Debt / | N7: EBITDA / | O7: EBITDA | P7: EBIT / | U7: EV / | V7: EV / | W7: P/E | X7: EV /
D8: Predicted | F8: ROIC | G8: ROE | H8: ROA | J8: Tot. Cap. | K8: EBITDA | L8: EBITDA | N8: Int. Exp. | O8: - Cpx/ Int. | P8: Int. Exp. | U8: EBITDA | V8: EBIT | X8: Sales
A9: Company | B9: Currency | C9: FYE | D9: Beta | F9: (%) | G9: (%) | H9: (%) | J9: (%) | K9: (x) | L9: (x) | N9: (x) | O9: (x) | P9: (x) | R9: Moody's | S9: S&P | U9: (x) | V9: (x) | W9: (x) | X9: (x)
A11: RHEINMETALL AG | B11: EUR | C11: =+[1]TargetCo!$E$10 -> 43465 | D11: ='Data & Forecasting '!D14 -> 0.34 | F11: =('Data & Forecasting '!J16*(1-'Data & Forecasting '!J23))/('Data & Forecasting '!J30+'Data & Forecasting '!D28-'Data & Forecasting '!D30) -> 0.13581861 | G11: ='Data & Forecasting '!J22/'Data & Forecasting '!J30 -> 0.18311364 | H11: ='Data & Forecasting '!J22/'Data & Forecasting '!J31 -> 0.061292631 | J11: ='Data & Forecasting '!D28/('Data & Forecasting '!D28+'Data & Forecasting '!J30) -> 0.26450937 | K11: ='Data & Forecasting '!D28/'Data & Forecasting '!J29 -> 0.92402746 | L11: =('Data & Forecasting '!D28+'Data & Forecasting '!D30)/'Data & Forecasting '!J29 -> 0.16887872 | N11: ='Data & Forecasting '!J29/'Data & Forecasting '!J17 -> 19.508929 | O11: =('Data & Forecasting '!J29-'Data & Forecasting '!J32)/'Data & Forecasting '!J17 -> 11.723214 | P11: ='Data & Forecasting '!J16/'Data & Forecasting '!J17 -> 15.044643 | R11: Baa1 | S11: =+[1]TargetCo!$E$12 -> NA | U11: ='Data & Forecasting '!D31/'Data & Forecasting '!J29 -> 32.496224 | V11: ='Data & Forecasting '!D31/'Data & Forecasting '!J16 -> 42.139021 | W11: ='Data & Forecasting '!D23/'Data & Forecasting '!J26 -> 68.711333 | X11: ='Data & Forecasting '!D31/'Data & Forecasting '!J11 -> 7.1468797
A13: Core Trading Reference Group
A14: BAE Systems (UK) | B14: GBP | C14: =+'[1]CompCo 1'!$E$10 -> 43465 | D14: 0 | F14: =('Data & Forecasting '!N36*(1-'Data & Forecasting '!AD36))/('Data & Forecasting '!T36+'Data & Forecasting '!Y36) -> 0.15358663 | G14: ='Data & Forecasting '!Q36/'Data & Forecasting '!Y36 -> 0.17274022 | H14: ='Data & Forecasting '!Q36/'Data & Forecasting '!AA36 -> 0.054725444 | J14: ='Data & Forecasting '!S36/('Data & Forecasting '!S36+'Data & Forecasting '!Y36) -> 0.45961974 | K14: ='Data & Forecasting '!S36/'Data & Forecasting '!K36 -> 2.2587319 | L14: ='Data & Forecasting '!T36/'Data & Forecasting '!K36 -> 1.0976641 | N14: ='Data & Forecasting '!K36/'Data & Forecasting '!AE36 -> 8.9186508 | O14: =('Data & Forecasting '!K36-'Data & Forecasting '!AB36)/'Data & Forecasting '!AE36 -> 6.7301587 | P14: ='Data & Forecasting '!N36/'Data & Forecasting '!AE36 -> 6.5912698 | R14: A3 | S14: BBB+ | U14: ='Data & Forecasting '!F36/'Data & Forecasting '!K36 -> 12.19386 | V14: ='Data & Forecasting '!F36/'Data & Forecasting '!N36 -> 16.499518 | W14: ='Data & Forecasting '!C36/'Data & Forecasting '!V36 -> 24.188846 | X14: ='Data & Forecasting '!F36/'Data & Forecasting '!H36 -> 1.7876003
A15: Thales (France) | B15: EUR | C15: =+'[1]CompCo 2'!$E$10 -> 43465 | D15: 0.13 | F15: =('Data & Forecasting '!N37*(1-'Data & Forecasting '!AD37))/('Data & Forecasting '!T37+'Data & Forecasting '!Y37) -> 0.2270214 | G15: ='Data & Forecasting '!Q37/'Data & Forecasting '!Y37 -> 0.2101974 | H15: ='Data & Forecasting '!Q37/'Data & Forecasting '!AA37 -> 0.042778263 | J15: ='Data & Forecasting '!S37/('Data & Forecasting '!S37+'Data & Forecasting '!Y37) -> 0.43477181 | K15: ='Data & Forecasting '!S37/'Data & Forecasting '!K37 -> 1.6016462 | L15: ='Data & Forecasting '!T37/'Data & Forecasting '!K37 -> 0.42814215 | N15: ='Data & Forecasting '!K37/'Data & Forecasting '!AE37 -> 13.42336 | O15: =('Data & Forecasting '!K37-'Data & Forecasting '!AB37)/'Data & Forecasting '!AE37 -> 10.769204 | P15: ='Data & Forecasting '!N37/'Data & Forecasting '!AE37 -> 9.6106629 | R15: A2 | S15: A | U15: ='Data & Forecasting '!F37/'Data & Forecasting '!K37 -> 12.769189 | V15: ='Data & Forecasting '!F37/'Data & Forecasting '!N37 -> 17.834922 | W15: ='Data & Forecasting '!C37/'Data & Forecasting '!V37 -> 28.196529 | X15: ='Data & Forecasting '!F37/'Data & Forecasting '!H37 -> 2.2076114
A16: Leonardo (Italy) | B16: EUR | C16: =+'[1]CompCo 3'!$E$10 -> 43465 | D16: 0.47 | F16: =('Data & Forecasting '!N38*(1-'Data & Forecasting '!AD38))/('Data & Forecasting '!T38+'Data & Forecasting '!Y38) -> 0.13891679 | G16: ='Data & Forecasting '!Q38/'Data & Forecasting '!Y38 -> 0.12803347 | H16: ='Data & Forecasting '!Q38/'Data & Forecasting '!AA38 -> 0.035469008 | J16: ='Data & Forecasting '!S38/('Data & Forecasting '!S38+'Data & Forecasting '!Y38) -> 0.31952452 | K16: ='Data & Forecasting '!S38/'Data & Forecasting '!K38 -> 1.8480856 | L16: ='Data & Forecasting '!T38/'Data & Forecasting '!K38 -> 0.26471799 | N16: ='Data & Forecasting '!K38/'Data & Forecasting '!AE38 -> 25.302083 | O16: =('Data & Forecasting '!K38-'Data & Forecasting '!AB38)/'Data & Forecasting '!AE38 -> 14.71875 | P16: ='Data & Forecasting '!N38/'Data & Forecasting '!AE38 -> 18.25 | R16: Baa3 | S16: BBB/A-2 | U16: ='Data & Forecasting '!F38/'Data & Forecasting '!K38 -> 11.921042 | V16: ='Data & Forecasting '!F38/'Data & Forecasting '!N38 -> 16.527517 | W16: ='Data & Forecasting '!C38/'Data & Forecasting '!V38 -> 23.131708 | X16: ='Data & Forecasting '!F38/'Data & Forecasting '!H38 -> 1.4847055
A17: Saab (Sweden) | B17: SEK | C17: =+'[1]CompCo 4'!$E$10 -> 43465 | D17: -0.02 | F17: =('Data & Forecasting '!N39*(1-'Data & Forecasting '!AD39))/('Data & Forecasting '!T39+'Data & Forecasting '!Y39) -> 0.12962806 | G17: ='Data & Forecasting '!Q39/'Data & Forecasting '!Y39 -> 0.14569873 | H17: ='Data & Forecasting '!Q39/'Data & Forecasting '!AA39 -> 0.050631896 | J17: ='Data & Forecasting '!S39/('Data & Forecasting '!S39+'Data & Forecasting '!Y39) -> 0.25340684 | K17: ='Data & Forecasting '!S39/'Data & Forecasting '!K39 -> 1.2962898 | L17: ='Data & Forecasting '!T39/'Data & Forecasting '!K39 -> 0.53494316 | N17: ='Data & Forecasting '!K39/'Data & Forecasting '!AE39 -> 56.735 | O17: =('Data & Forecasting '!K39-'Data & Forecasting '!AB39)/'Data & Forecasting '!AE39 -> 20.625 | P17: ='Data & Forecasting '!N39/'Data & Forecasting '!AE39 -> 40.33 | R17: A2 | S17: BBB+ | U17: ='Data & Forecasting '!F39/'Data & Forecasting '!K39 -> 25.636841 | V17: ='Data & Forecasting '!F39/'Data & Forecasting '!N39 -> 36.065117 | W17: ='Data & Forecasting '!C39/'Data & Forecasting '!V39 -> 45.11106 | X17: ='Data & Forecasting '!F39/'Data & Forecasting '!H39 -> 3.6755014
A18: Kongsberg Gruppen (Norway) | B18: NOK | C18: =+'[1]CompCo 5'!$E$10 -> 43465 | D18: 0.45 | F18: =('Data & Forecasting '!N40*(1-'Data & Forecasting '!AD40))/('Data & Forecasting '!T40+'Data & Forecasting '!Y40) -> 0.61986635 | G18: ='Data & Forecasting '!Q40/'Data & Forecasting '!Y40 -> 0.35221435 | H18: ='Data & Forecasting '!Q40/'Data & Forecasting '!AA40 -> 0.096846079 | J18: ='Data & Forecasting '!S40/('Data & Forecasting '!S40+'Data & Forecasting '!Y40) -> 0.17932689 | K18: ='Data & Forecasting '!S40/'Data & Forecasting '!K40 -> 0.44756894 | L18: ='Data & Forecasting '!T40/'Data & Forecasting '!K40 -> -0.99165457 | N18: ='Data & Forecasting '!K40/'Data & Forecasting '!AE40 -> 74.993197 | O18: =('Data & Forecasting '!K40-'Data & Forecasting '!AB40)/'Data & Forecasting '!AE40 -> 55.564626 | P18: ='Data & Forecasting '!N40/'Data & Forecasting '!AE40 -> 63.238095 | R18: B2 | S18: B- | U18: ='Data & Forecasting '!F40/'Data & Forecasting '!K40 -> 19.640985 | V18: ='Data & Forecasting '!F40/'Data & Forecasting '!N40 -> 23.291977 | W18: ='Data & Forecasting '!C40/'Data & Forecasting '!V40 -> 28.599801 | X18: ='Data & Forecasting '!F40/'Data & Forecasting '!H40 -> 3.6949814
A20: Mean | D20: =+AVERAGE(D14:D18) -> 0.206 | F20: =+AVERAGE(F14:F18) -> 0.25380385 | G20: =+AVERAGE(G14:G18) -> 0.20177683 | H20: =+AVERAGE(H14:H18) -> 0.056090138 | J20: =+AVERAGE(J14:J18) -> 0.32932996 | K20: =+AVERAGE(K14:K18) -> 1.4904645 | L20: =+AVERAGE(L14:L18) -> 0.26676256 | N20: =+AVERAGE(N14:N18) -> 35.874458 | O20: =+AVERAGE(O14:O18) -> 21.681548 | P20: =+AVERAGE(P14:P18) -> 27.604006 | U20: =+AVERAGE(U14:U18) -> 16.432383 | V20: =+AVERAGE(V14:V18) -> 22.04381 | W20: =+AVERAGE(W14:W18) -> 29.845589 | X20: =+AVERAGE(X14:X18) -> 2.57008
A21: Median | D21: =MEDIAN(D14:D18) -> 0.13 | F21: =MEDIAN(F14:F18) -> 0.15358663 | G21: =MEDIAN(G14:G18) -> 0.17274022 | H21: =MEDIAN(H14:H18) -> 0.050631896 | J21: =MEDIAN(J14:J18) -> 0.31952452 | K21: =MEDIAN(K14:K18) -> 1.6016462 | L21: =MEDIAN(L14:L18) -> 0.42814215 | N21: =MEDIAN(N14:N18) -> 25.302083 | O21: =MEDIAN(O14:O18) -> 14.71875 | P21: =MEDIAN(P14:P18) -> 18.25 | U21: =MEDIAN(U14:U18) -> 12.769189 | V21: =MEDIAN(V14:V18) -> 17.834922 | W21: =MEDIAN(W14:W18) -> 28.196529 | X21: =MEDIAN(X14:X18) -> 2.2076114
A23: Extendend Trading Reference Group
A24: Lockheed Martin (US) | B24: USD | C24: =+'[1]CompCo 6'!$E$10 -> 43465 | D24: 0.2 | F24: =('Data & Forecasting '!N43*(1-'Data & Forecasting '!AD43))/('Data & Forecasting '!Y43+'Data & Forecasting '!T43) -> 0.26953511 | G24: ='Data & Forecasting '!Q43/'Data & Forecasting '!Y43 -> 0.7464663 | H24: ='Data & Forecasting '!Q43/'Data & Forecasting '!AA43 -> 0.083840241 | J24: ='Data & Forecasting '!S43/('Data & Forecasting '!S43+'Data & Forecasting '!Y43) -> 0.76351993 | K24: ='Data & Forecasting '!S43/'Data & Forecasting '!K43 -> 2.3040985 | L24: ='Data & Forecasting '!T43/'Data & Forecasting '!K43 -> 1.8665322 | N24: ='Data & Forecasting '!K43/'Data & Forecasting '!AE43 -> 8.4239714 | O24: =('Data & Forecasting '!K43-'Data & Forecasting '!AB43)/'Data & Forecasting '!AE43 -> 6.9490161 | P24: ='Data & Forecasting '!N43/'Data & Forecasting '!AE43 -> 6.9150268 | R24: A2 | S24: A- | U24: ='Data & Forecasting '!F43/'Data & Forecasting '!K43 -> 13.954944 | V24: ='Data & Forecasting '!F43/'Data & Forecasting '!N43 -> 17.000086 | W24: ='Data & Forecasting '!C43/'Data & Forecasting '!V43 -> 22.692578 | X24: ='Data & Forecasting '!F43/'Data & Forecasting '!H43 -> 1.751248
A25: Northrop Grumman (US) | B25: USD | C25: =+'[1]CompCo 7'!$E$10 -> 43465 | D25: 0.01 | F25: =('Data & Forecasting '!N44*(1-'Data & Forecasting '!AD44))/('Data & Forecasting '!Y44+'Data & Forecasting '!T44) -> 0.13566052 | G25: ='Data & Forecasting '!Q44/'Data & Forecasting '!Y44 -> 0.25080964 | H25: ='Data & Forecasting '!Q44/'Data & Forecasting '!AA44 -> 0.081398291 | J25: ='Data & Forecasting '!S44/('Data & Forecasting '!S44+'Data & Forecasting '!Y44) -> 0.50511976 | K25: ='Data & Forecasting '!S44/'Data & Forecasting '!K44 -> 2.8445596 | L25: ='Data & Forecasting '!T44/'Data & Forecasting '!K44 -> 1.7982617 | N25: ='Data & Forecasting '!K44/'Data & Forecasting '!AE44 -> 8.9969925 | O25: =('Data & Forecasting '!K44-'Data & Forecasting '!AB44)/'Data & Forecasting '!AE44 -> 6.8165414 | P25: ='Data & Forecasting '!N44/'Data & Forecasting '!AE44 -> 6.7834586 | R25: Baa2 | S25: BBB+ | U25: ='Data & Forecasting '!F44/'Data & Forecasting '!K44 -> 15.436412 | V25: ='Data & Forecasting '!F44/'Data & Forecasting '!N44 -> 20.473521 | W25: ='Data & Forecasting '!C44/'Data & Forecasting '!V44 -> 19.51149 | X25: ='Data & Forecasting '!F44/'Data & Forecasting '!H44 -> 2.2013646
A26: General Dynamics (US) | B26: USD | C26: =+'[1]CompCo 8'!$E$10 -> 43465 | D26: 0.37 | F26: =('Data & Forecasting '!N45*(1-'Data & Forecasting '!AD45))/('Data & Forecasting '!Y45+'Data & Forecasting '!T45) -> 0.11583963 | G26: ='Data & Forecasting '!Q45/'Data & Forecasting '!Y45 -> 0.16431192 | H26: ='Data & Forecasting '!Q45/'Data & Forecasting '!AA45 -> 0.073538402 | J26: ='Data & Forecasting '!S45/('Data & Forecasting '!S45+'Data & Forecasting '!Y45) -> 0.27643952 | K26: ='Data & Forecasting '!S45/'Data & Forecasting '!K45 -> 1.558758 | L26: ='Data & Forecasting '!T45/'Data & Forecasting '!K45 -> 0.9044586 | N26: ='Data & Forecasting '!K45/'Data & Forecasting '!AE45 -> 15.621891 | O26: =('Data & Forecasting '!K45-'Data & Forecasting '!AB45)/'Data & Forecasting '!AE45 -> 12.733831 | P26: ='Data & Forecasting '!N45/'Data & Forecasting '!AE45 -> 13.323383 | R26: A2 | S26: A | U26: ='Data & Forecasting '!F45/'Data & Forecasting '!K45 -> 15.589268 | V26: ='Data & Forecasting '!F45/'Data & Forecasting '!N45 -> 18.278678 | W26: ='Data & Forecasting '!C45/'Data & Forecasting '!V45 -> 21.905131 | X26: ='Data & Forecasting '!F45/'Data & Forecasting '!H45 -> 1.8629991
A27: Safran (France) | B27: EUR | C27: =+'[1]CompCo 10'!$E$10 -> 43465 | D27: 0.92 | F27: =('Data & Forecasting '!N46*(1-'Data & Forecasting '!AD46))/('Data & Forecasting '!Y46+'Data & Forecasting '!T46) -> 0.32056262 | G27: ='Data & Forecasting '!Q46/'Data & Forecasting '!Y46 -> 0.48365793 | H27: ='Data & Forecasting '!Q46/'Data & Forecasting '!AA46 -> 0.11610638 | J27: ='Data & Forecasting '!S46/('Data & Forecasting '!S46+'Data & Forecasting '!Y46) -> 0.26408451 | K27: ='Data & Forecasting '!S46/'Data & Forecasting '!K46 -> 0.75908767 | L27: ='Data & Forecasting '!T46/'Data & Forecasting '!K46 -> -0.20869565 | N27: ='Data & Forecasting '!K46/'Data & Forecasting '!AE46 -> 51.962963 | O27: =('Data & Forecasting '!K46-'Data & Forecasting '!AB46)/'Data & Forecasting '!AE46 -> 38.62963 | P27: ='Data & Forecasting '!N46/'Data & Forecasting '!AE46 -> 38.496296 | R27: A- | S27: =+'[1]CompCo 10'!$E$12 -> NA | U27: ='Data & Forecasting '!F46/'Data & Forecasting '!K46 -> 17.471194 | V27: ='Data & Forecasting '!F46/'Data & Forecasting '!N46 -> 23.582918 | W27: ='Data & Forecasting '!C46/'Data & Forecasting '!V46 -> 17.280817 | X27: ='Data & Forecasting '!F46/'Data & Forecasting '!H46 -> 3.9120439
A28: Rolls-Royce (UK) | B28: GBP | C28: =+'[1]CompCo 9'!$E$10 -> 43465 | D28: 1.16 | F28: =('Data & Forecasting '!N47*(1-'Data & Forecasting '!AD47))/('Data & Forecasting '!Y47+'Data & Forecasting '!T47) -> 2.9414773 | G28: ='Data & Forecasting '!Q47/'Data & Forecasting '!Y47 -> 2.1216854 | H28: ='Data & Forecasting '!Q47/'Data & Forecasting '!AA47 -> 0.15324675 | J28: ='Data & Forecasting '!S47/('Data & Forecasting '!S47+'Data & Forecasting '!Y47) -> 0.60811388 | K28: ='Data & Forecasting '!S47/'Data & Forecasting '!K47 -> 0.97936726 | L28: ='Data & Forecasting '!T47/'Data & Forecasting '!K47 -> -0.40394315 | N28: ='Data & Forecasting '!K47/'Data & Forecasting '!AE47 -> 14.443709 | O28: =('Data & Forecasting '!K47-'Data & Forecasting '!AB47)/'Data & Forecasting '!AE47 -> 11.182119 | P28: ='Data & Forecasting '!N47/'Data & Forecasting '!AE47 -> 11.463576 | R28: A3 | S28: BBB | U28: ='Data & Forecasting '!F47/'Data & Forecasting '!K47 -> 30.005355 | V28: ='Data & Forecasting '!F47/'Data & Forecasting '!N47 -> 37.805708 | W28: ='Data & Forecasting '!C47/'Data & Forecasting '!V47 -> 22.709358 | X28: ='Data & Forecasting '!F47/'Data & Forecasting '!H47 -> 6.5249195
A30: Mean | D30: =+AVERAGE(D24:D28) -> 0.532 | F30: =+AVERAGE(F24:F28) -> 0.75661503 | G30: =+AVERAGE(G24:G28) -> 0.75338625 | H30: =+AVERAGE(H24:H28) -> 0.10162601 | J30: =+AVERAGE(J24:J28) -> 0.48345552 | K30: =+AVERAGE(K24:K28) -> 1.6891742 | L30: =+AVERAGE(L24:L28) -> 0.79132274 | N30: =+AVERAGE(N24:N28) -> 19.889905 | O30: =+AVERAGE(O24:O28) -> 15.262227 | P30: =+AVERAGE(P24:P28) -> 15.396348 | U30: =+AVERAGE(U24:U28) -> 18.491434 | V30: =+AVERAGE(V24:V28) -> 23.428182 | W30: =+AVERAGE(W24:W28) -> 20.819875 | X30: =+AVERAGE(X24:X28) -> 3.250515
A31: Median | D31: =MEDIAN(D24:D28) -> 0.37 | F31: =MEDIAN(F24:F28) -> 0.26953511 | G31: =MEDIAN(G24:G28) -> 0.48365793 | H31: =MEDIAN(H24:H28) -> 0.083840241 | J31: =MEDIAN(J24:J28) -> 0.50511976 | K31: =MEDIAN(K24:K28) -> 1.558758 | L31: =MEDIAN(L24:L28) -> 0.9044586 | N31: =MEDIAN(N24:N28) -> 14.443709 | O31: =MEDIAN(O24:O28) -> 11.182119 | P31: =MEDIAN(P24:P28) -> 11.463576 | U31: =MEDIAN(U24:U28) -> 15.589268 | V31: =MEDIAN(V24:V28) -> 20.473521 | W31: =MEDIAN(W24:W28) -> 21.905131 | X31: =MEDIAN(X24:X28) -> 2.2013646
A33: Overall
A35: Mean | D35: =+AVERAGE(D14:D18,D24:D28) -> 0.369 | F35: =+AVERAGE(F14:F18,F24:F28) -> 0.50520944 | G35: =+AVERAGE(G14:G18,G24:G28) -> 0.47758154 | H35: =+AVERAGE(H14:H18,H24:H28) -> 0.078858076 | J35: =+AVERAGE(J14:J18,J24:J28) -> 0.40639274 | K35: =+AVERAGE(K14:K18,K24:K28) -> 1.5898193 | L35: =+AVERAGE(L14:L18,L24:L28) -> 0.52904265 | N35: =+AVERAGE(N14:N18,N24:N28) -> 27.882182 | O35: =+AVERAGE(O14:O18,O24:O28) -> 18.471888 | P35: =+AVERAGE(P14:P18,P24:P28) -> 21.500177 | U35: =+AVERAGE(U14:U18,U24:U28) -> 17.461909 | V35: =+AVERAGE(V14:V18,V24:V28) -> 22.735996 | W35: =+AVERAGE(W14:W18,W24:W28) -> 25.332732 | X35: =+AVERAGE(X14:X18,X24:X28) -> 2.9102975
A36: Median | D36: =+AVERAGE(D14:D18,D24:D28) -> 0.369 | F36: =+AVERAGE(F14:F18,F24:F28) -> 0.50520944 | G36: =+AVERAGE(G14:G18,G24:G28) -> 0.47758154 | H36: =+AVERAGE(H14:H18,H24:H28) -> 0.078858076 | J36: =+MEDIAN(J14:J18,J24:J28) -> 0.37714817 | K36: =+MEDIAN(K14:K18,K24:K28) -> 1.5802021 | L36: =+MEDIAN(L14:L18,L24:L28) -> 0.48154265 | N36: =+MEDIAN(N14:N18,N24:N28) -> 15.0328 | O36: =+MEDIAN(O14:O18,O24:O28) -> 11.957975 | P36: =+MEDIAN(P14:P18,P24:P28) -> 12.39348 | U36: =+MEDIAN(U14:U18,U24:U28) -> 15.51284 | V36: =+MEDIAN(V14:V18,V24:V28) -> 19.376099 | W36: =+MEDIAN(W14:W18,W24:W28) -> 22.920533 | X36: =+MEDIAN(X14:X18,X24:X28) -> 2.204488
A38: High | D38: =+MAX(D14:D18,D24:D28) -> 1.16 | F38: =+MAX(F14:F18,F24:F28) -> 2.9414773 | G38: =+MAX(G14:G18,G24:G28) -> 2.1216854 | H38: =+MAX(H14:H18,H24:H28) -> 0.15324675 | J38: =+MAX(J14:J18,J24:J28) -> 0.76351993 | K38: =+MAX(K14:K18,K24:K28) -> 2.8445596 | L38: =+MAX(L14:L18,L24:L28) -> 1.8665322 | N38: =+MAX(N14:N18,N24:N28) -> 74.993197 | O38: =+MAX(O14:O18,O24:O28) -> 55.564626 | P38: =+MAX(P14:P18,P24:P28) -> 63.238095 | U38: =+MAX(U14:U18,U24:U28) -> 30.005355 | V38: =+MAX(V14:V18,V24:V28) -> 37.805708 | W38: =+MAX(W14:W18,W24:W28) -> 45.11106 | X38: =+MAX(X14:X18,X24:X28) -> 6.5249195
A39: Low | D39: =+MAX(D14:D18,D24:D28) -> 1.16 | F39: =+MIN(F14:F18,F24:F28) -> 0.11583963 | G39: =+MIN(G14:G18,G24:G28) -> 0.12803347 | H39: =+MIN(H14:H18,H24:H28) -> 0.035469008 | J39: =+MIN(J14:J18,J24:J28) -> 0.17932689 | K39: =+MIN(K14:K18,K24:K28) -> 0.44756894 | L39: =+MIN(L14:L18,L24:L28) -> -0.99165457 | N39: =+MIN(N14:N18,N24:N28) -> 8.4239714 | O39: =+MIN(O14:O18,O24:O28) -> 6.7301587 | P39: =+MIN(P14:P18,P24:P28) -> 6.5912698 | U39: =+MIN(U14:U18,U24:U28) -> 11.921042 | V39: =+MIN(V14:V18,V24:V28) -> 16.499518 | W39: =+MIN(W14:W18,W24:W28) -> 17.280817 | X39: =+MIN(X14:X18,X24:X28) -> 1.4847055

Sheet Benchmarking Analysis (x) NTM
A1: RHEINMETALL AG
A2: Benchmarking Analysis – Multiples Analysis NTM
C6: General | F6: NTM Return on Investment | J6: NTM Leverage Ratios | N6: NTM Coverage Ratios | R6: Credit Ratings | U6: NTM Valuation Multiples
J7: Debt / | K7: Debt / | L7: Net Debt / | N7: EBITDA / | O7: EBITDA | P7: EBIT / | U7: EV / | V7: EV / | W7: P/E | X7: EV /
D8: Predicted | F8: ROIC | G8: ROE | H8: ROA | J8: Tot. Cap. | K8: EBITDA | L8: EBITDA | N8: Int. Exp. | O8: - Cpx/ Int. | P8: Int. Exp. | U8: EBITDA | V8: EBIT | X8: Sales
A9: Company | B9: Ticker | C9: FYE | D9: Beta | F9: (%) | G9: (%) | H9: (%) | J9: (%) | K9: (x) | L9: (x) | N9: (x) | O9: (x) | P9: (x) | R9: Moody's | S9: S&P | U9: (x) | V9: (x) | W9: (x) | X9: (x)
A11: RHEINMETALL AG | B11: EUR | C11: =+[1]TargetCo!$E$10 -> 43465 | D11: 0.34 | F11: =('Data & Forecasting '!K16*(1-'Data & Forecasting '!K23))/('Data & Forecasting '!J30+'Data & Forecasting '!D28+'Data & Forecasting '!D30) -> 0.32882834 | G11: ='Data & Forecasting '!K22/'Data & Forecasting '!J30 -> 0.29457544 | H11: ='Data & Forecasting '!K22/'Data & Forecasting '!J31 -> 0.098601628 | J11: ='Data & Forecasting '!D28/('Data & Forecasting '!D28+'Data & Forecasting '!J30) -> 0.26450937 | K11: ='Data & Forecasting '!D28/'Data & Forecasting '!K29 -> 0.62701863 | L11: =('Data & Forecasting '!D28+'Data & Forecasting '!D30)/'Data & Forecasting '!K29 -> 0.11459627 | N11: =('Data & Forecasting '!K29)/'Data & Forecasting '!K17 -> 32.2 | O11: =('Data & Forecasting '!K29-'Data & Forecasting '!K32)/'Data & Forecasting '!K17 -> 16.95 | P11: ='Data & Forecasting '!K16/'Data & Forecasting '!K17 -> 26.27 | R11: Baa1 | S11: =+[1]TargetCo!$E$12 -> NA | U11: ='Data & Forecasting '!D31/'Data & Forecasting '!K29 -> 22.051009 | V11: ='Data & Forecasting '!D31/'Data & Forecasting '!K16 -> 27.028645 | W11: ='Data & Forecasting '!D23/'Data & Forecasting '!K26 -> 42.71226 | X11: ='Data & Forecasting '!D31/'Data & Forecasting '!J11 -> 7.1468797
A13: Core Trading Reference Group
A14: BAE Systems (UK) | B14: GBP | C14: =+'[1]CompCo 1'!$E$10 -> 43465 | D14: 0 | F14: =('Data & Forecasting '!O36*(1-'Data & Forecasting '!AD36))/('Data & Forecasting '!Y36+'Data & Forecasting '!T36) -> 0.16773398 | G14: ='Data & Forecasting '!R36/'Data & Forecasting '!Y36 -> 0.19393482 | H14: ='Data & Forecasting '!R36/'Data & Forecasting '!AA36 -> 0.061440059 | J14: =('Data & Forecasting '!S36)/('Data & Forecasting '!S36+'Data & Forecasting '!Y36) -> 0.45961974 | K14: ='Data & Forecasting '!S36/'Data & Forecasting '!L36 -> 2.1867327 | L14: ='Data & Forecasting '!T36/'Data & Forecasting '!L36 -> 1.062675 | N14: ='Data & Forecasting '!L36/'Data & Forecasting '!AE36 -> 9.2123016 | O14: =('Data & Forecasting '!L36-'Data & Forecasting '!AB36)/'Data & Forecasting '!AE36 -> 7.0238095 | P14: ='Data & Forecasting '!O36/'Data & Forecasting '!AE36 -> 7.1984127 | R14: A3 | S14: BBB+ | U14: ='Data & Forecasting '!F36/'Data & Forecasting '!L36 -> 11.805169 | V14: ='Data & Forecasting '!F36/'Data & Forecasting '!O36 -> 15.107883 | W14: ='Data & Forecasting '!C36/'Data & Forecasting '!W36 -> 21.545313 | X14: ='Data & Forecasting '!F36/'Data & Forecasting '!I36 -> 1.6531865
A15: Thales (France) | B15: EUR | C15: =+'[1]CompCo 2'!$E$10 -> 43465 | D15: 0.13 | F15: =('Data & Forecasting '!O37*(1-'Data & Forecasting '!AD37))/('Data & Forecasting '!Y37+'Data & Forecasting '!T37) -> 0.24922641 | G15: ='Data & Forecasting '!R37/'Data & Forecasting '!Y37 -> 0.2324093 | H15: ='Data & Forecasting '!R37/'Data & Forecasting '!AA37 -> 0.047298712 | J15: =('Data & Forecasting '!S37)/('Data & Forecasting '!S37+'Data & Forecasting '!Y37) -> 0.43477181 | K15: ='Data & Forecasting '!S37/'Data & Forecasting '!L37 -> 1.6389037 | L15: ='Data & Forecasting '!T37/'Data & Forecasting '!L37 -> 0.4381016 | N15: ='Data & Forecasting '!L37/'Data & Forecasting '!AE37 -> 13.118204 | O15: =('Data & Forecasting '!L37-'Data & Forecasting '!AB37)/'Data & Forecasting '!AE37 -> 10.464048 | P15: ='Data & Forecasting '!O37/'Data & Forecasting '!AE37 -> 10.550684 | R15: A2 | S15: A | U15: ='Data & Forecasting '!F37/'Data & Forecasting '!L37 -> 13.066226 | V15: ='Data & Forecasting '!F37/'Data & Forecasting '!O37 -> 16.245906 | W15: ='Data & Forecasting '!C37/'Data & Forecasting '!W37 -> 25.50172 | X15: ='Data & Forecasting '!F37/'Data & Forecasting '!I37 -> 2.0533504
A16: Leonardo (Italy) | B16: EUR | C16: =+'[1]CompCo 3'!$E$10 -> 43465 | D16: 0.47 | F16: =('Data & Forecasting '!O38*(1-'Data & Forecasting '!AD38))/('Data & Forecasting '!Y38+'Data & Forecasting '!T38) -> 0.16230746 | G16: ='Data & Forecasting '!R38/'Data & Forecasting '!Y38 -> 0.13169456 | H16: ='Data & Forecasting '!R38/'Data & Forecasting '!AA38 -> 0.036483236 | J16: =('Data & Forecasting '!S38)/('Data & Forecasting '!S38+'Data & Forecasting '!Y38) -> 0.31952452 | K16: ='Data & Forecasting '!S38/'Data & Forecasting '!L38 -> 1.6311773 | L16: ='Data & Forecasting '!T38/'Data & Forecasting '!L38 -> 0.23364826 | N16: ='Data & Forecasting '!L38/'Data & Forecasting '!AE38 -> 28.666667 | O16: =('Data & Forecasting '!L38-'Data & Forecasting '!AB38)/'Data & Forecasting '!AE38 -> 18.083333 | P16: ='Data & Forecasting '!O38/'Data & Forecasting '!AE38 -> 21.322917 | R16: Baa3 | S16: BBB/A-2 | U16: ='Data & Forecasting '!F38/'Data & Forecasting '!L38 -> 10.521879 | V16: ='Data & Forecasting '!F38/'Data & Forecasting '!O38 -> 14.145682 | W16: ='Data & Forecasting '!C38/'Data & Forecasting '!W38 -> 22.48865 | X16: ='Data & Forecasting '!F38/'Data & Forecasting '!I38 -> 1.3621324
